Workbook

Sheet Cover
B3: PUT YOUR STARTUP NAME HERE
B4: 3-Year Financial Projection
B6: DETERMINE YOUR PRICING MODEL (e.g. Free tier + Pro $X/mo)
B7: Last Updated: 06/23/2026
B8: Active Case: | E8: =Detailed!$C$3
B10: FILL IN WHAT YOU HAVE IN THE BANK NOW — also set Case Filter → Initial funding (C53)
B11: Generic 3-year SaaS template — edit orange cells, then use the Growth Curve Editor for signups.
B13: Legend:
D14: Hardcoded input
D15: Formula
D16: Links to another tab

Sheet Start Here
B2: How to use this model (4 scenarios)
B4: Case Filter C1: 0=Base | 1=Upside | 2=Downside | 3=Upside-Upside
B5: Start with Base Case only. Use the Growth Curve Editor to shape signups, then tune other scenarios.
B7: Orange cells = your inputs. Yellow monthly rows on Case Filter = growth drivers (edit Base Case first).
B8: 4. Set unit economics (price, COGS, salary, initial funding) on Case Filter column C
B9: 5. Detailed tab fills automatically; Summary shows Year 1–3 totals
B11: IF YOU SEE #VALUE! ERRORS:
B12: • Press Cmd+Shift+K (Mac) or Ctrl+Alt+F9 (Windows) to force recalculate
B13: • Ensure Case Filter C1 is 0, 1, or 2 (not blank)
B14: • Re-open the file after saving (old version had circular formula bugs — fixed)
B16: KEY ASSUMPTIONS YOU SHOULD SET:
B18: Growth (Case Filter, yellow monthly rows):
... B36: • Composer runs: 18–28/mo per Pro sub

Sheet Summary
B1: PUT YOUR STARTUP NAME HERE
B2: 3-Year Projection — Summary
B3: ="Active Case: "&Detailed!C3
B5: ($ Actual) | C5: Year 1 | D5: Year 2 | E5: Year 3
A7: x | B7: User & Subscriber Statistics
B9: New signups | C9: =SUM(Detailed!C9,Detailed!D9,Detailed!E9,Detailed!F9,Detailed!G9,Detailed!H9,Detailed!I9,Detailed!J9,Detailed!K9,Detailed!L9,Detailed!M9,Detailed!N9) | D9: =SUM(Detailed!O9,Detailed!P9,Detailed!Q9,Detailed!R9,Detailed!S9,Detailed!T9,Detailed!U9,Detailed!V9,Detailed!W9,Detailed!X9,Detailed!Y9,Detailed!Z9) | E9: =SUM(Detailed!AA9,Detailed!AB9,Detailed!AC9,Detailed!AD9,Detailed!AE9,Detailed!AF9,Detailed!AG9,Detailed!AH9,Detailed!AI9,Detailed!AJ9,Detailed!AK9,Detailed!AL9)
B10: Ending Pro subscribers | C10: =Detailed!N13 | D10: =Detailed!Z13 | E10: =Detailed!AL13
B11: Ending total users | C11: =Detailed!N14 | D11: =Detailed!Z14 | E11: =Detailed!AL14
B12: Pro as % of users (year end) | C12: =Detailed!N16 | D12: =Detailed!Z16 | E12: =Detailed!AL16
B13: Average Pro subscribers | C13: =AVERAGE(Detailed!C13,Detailed!D13,Detailed!E13,Detailed!F13,Detailed!G13,Detailed!H13,Detailed!I13,Detailed!J13,Detailed!K13,Detailed!L13,Detailed!M13,Detailed!N13) | D13: =AVERAGE(Detailed!O13,Detailed!P13,Detailed!Q13,Detailed!R13,Detailed!S13,Detailed!T13,Detailed!U13,Detailed!V13,Detailed!W13,Detailed!X13,Detailed!Y13,Detailed!Z13) | E13: =AVERAGE(Detailed!AA13,Detailed!AB13,Detailed!AC13,Detailed!AD13,Detailed!AE13,Detailed!AF13,Detailed!AG13,Detailed!AH13,Detailed!AI13,Detailed!AJ13,Detailed!AK13,Detailed!AL13)
A15: x | B15: P&L Summary
B17: Gross MRR | C17: =SUM(Detailed!C19,Detailed!D19,Detailed!E19,Detailed!F19,Detailed!G19,Detailed!H19,Detailed!I19,Detailed!J19,Detailed!K19,Detailed!L19,Detailed!M19,Detailed!N19) | D17: =SUM(Detailed!O19,Detailed!P19,Detailed!Q19,Detailed!R19,Detailed!S19,Detailed!T19,Detailed!U19,Detailed!V19,Detailed!W19,Detailed!X19,Detailed!Y19,Detailed!Z19) | E17: =SUM(Detailed!AA19,Detailed!AB19,Detailed!AC19,Detailed!AD19,Detailed!AE19,Detailed!AF19,Detailed!AG19,Detailed!AH19,Detailed!AI19,Detailed!AJ19,Detailed!AK19,Detailed!AL19)
B18: Net revenue | C18: =SUM(Detailed!C21,Detailed!D21,Detailed!E21,Detailed!F21,Detailed!G21,Detailed!H21,Detailed!I21,Detailed!J21,Detailed!K21,Detailed!L21,Detailed!M21,Detailed!N21) | D18: =SUM(Detailed!O21,Detailed!P21,Detailed!Q21,Detailed!R21,Detailed!S21,Detailed!T21,Detailed!U21,Detailed!V21,Detailed!W21,Detailed!X21,Detailed!Y21,Detailed!Z21) | E18: =SUM(Detailed!AA21,Detailed!AB21,Detailed!AC21,Detailed!AD21,Detailed!AE21,Detailed!AF21,Detailed!AG21,Detailed!AH21,Detailed!AI21,Detailed!AJ21,Detailed!AK21,Detailed!AL21)
B19: Total variable COGS | C19: =SUM(Detailed!C25,Detailed!D25,Detailed!E25,Detailed!F25,Detailed!G25,Detailed!H25,Detailed!I25,Detailed!J25,Detailed!K25,Detailed!L25,Detailed!M25,Detailed!N25) | D19: =SUM(Detailed!O25,Detailed!P25,Detailed!Q25,Detailed!R25,Detailed!S25,Detailed!T25,Detailed!U25,Detailed!V25,Detailed!W25,Detailed!X25,Detailed!Y25,Detailed!Z25) | E19: =SUM(Detailed!AA25,Detailed!AB25,Detailed!AC25,Detailed!AD25,Detailed!AE25,Detailed!AF25,Detailed!AG25,Detailed!AH25,Detailed!AI25,Detailed!AJ25,Detailed!AK25,Detailed!AL25)
B20: Gross profit | C20: =SUM(Detailed!C26,Detailed!D26,Detailed!E26,Detailed!F26,Detailed!G26,Detailed!H26,Detailed!I26,Detailed!J26,Detailed!K26,Detailed!L26,Detailed!M26,Detailed!N26) | D20: =SUM(Detailed!O26,Detailed!P26,Detailed!Q26,Detailed!R26,Detailed!S26,Detailed!T26,Detailed!U26,Detailed!V26,Detailed!W26,Detailed!X26,Detailed!Y26,Detailed!Z26) | E20: =SUM(Detailed!AA26,Detailed!AB26,Detailed!AC26,Detailed!AD26,Detailed!AE26,Detailed!AF26,Detailed!AG26,Detailed!AH26,Detailed!AI26,Detailed!AJ26,Detailed!AK26,Detailed!AL26)
B21: Total operating expenses | C21: =SUM(Detailed!C36,Detailed!D36,Detailed!E36,Detailed!F36,Detailed!G36,Detailed!H36,Detailed!I36,Detailed!J36,Detailed!K36,Detailed!L36,Detailed!M36,Detailed!N36) | D21: =SUM(Detailed!O36,Detailed!P36,Detailed!Q36,Detailed!R36,Detailed!S36,Detailed!T36,Detailed!U36,Detailed!V36,Detailed!W36,Detailed!X36,Detailed!Y36,Detailed!Z36) | E21: =SUM(Detailed!AA36,Detailed!AB36,Detailed!AC36,Detailed!AD36,Detailed!AE36,Detailed!AF36,Detailed!AG36,Detailed!AH36,Detailed!AI36,Detailed!AJ36,Detailed!AK36,Detailed!AL36)
B22: EBITDA | C22: =SUM(Detailed!C38,Detailed!D38,Detailed!E38,Detailed!F38,Detailed!G38,Detailed!H38,Detailed!I38,Detailed!J38,Detailed!K38,Detailed!L38,Detailed!M38,Detailed!N38) | D22: =SUM(Detailed!O38,Detailed!P38,Detailed!Q38,Detailed!R38,Detailed!S38,Detailed!T38,Detailed!U38,Detailed!V38,Detailed!W38,Detailed!X38,Detailed!Y38,Detailed!Z38) | E22: =SUM(Detailed!AA38,Detailed!AB38,Detailed!AC38,Detailed!AD38,Detailed!AE38,Detailed!AF38,Detailed!AG38,Detailed!AH38,Detailed!AI38,Detailed!AJ38,Detailed!AK38,Detailed!AL38)
B23: Free cash flow | C23: =SUM(Detailed!C40,Detailed!D40,Detailed!E40,Detailed!F40,Detailed!G40,Detailed!H40,Detailed!I40,Detailed!J40,Detailed!K40,Detailed!L40,Detailed!M40,Detailed!N40) | D23: =SUM(Detailed!O40,Detailed!P40,Detailed!Q40,Detailed!R40,Detailed!S40,Detailed!T40,Detailed!U40,Detailed!V40,Detailed!W40,Detailed!X40,Detailed!Y40,Detailed!Z40) | E23: =SUM(Detailed!AA40,Detailed!AB40,Detailed!AC40,Detailed!AD40,Detailed!AE40,Detailed!AF40,Detailed!AG40,Detailed!AH40,Detailed!AI40,Detailed!AJ40,Detailed!AK40,Detailed!AL40)
B24: Gross margin % | C24: =IF(C18=0,"NM",C20/C18) | D24: =IF(D18=0,"NM",D20/D18) | E24: =IF(E18=0,"NM",E20/E18)
B25: EBITDA margin % | C25: =IF(C18=0,"NM",C22/C18) | D25: =IF(D18=0,"NM",D22/D18) | E25: =IF(E18=0,"NM",E22/E18)
A27: x | B27: Cash & Funding
B29: Initial funding | C29: ='Case Filter'!$C$48
B30: Minimum cash balance (year) | C30: =MIN(Detailed!C45,Detailed!D45,Detailed!E45,Detailed!F45,Detailed!G45,Detailed!H45,Detailed!I45,Detailed!J45,Detailed!K45,Detailed!L45,Detailed!M45,Detailed!N45) | D30: =MIN(Detailed!O45,Detailed!P45,Detailed!Q45,Detailed!R45,Detailed!S45,Detailed!T45,Detailed!U45,Detailed!V45,Detailed!W45,Detailed!X45,Detailed!Y45,Detailed!Z45) | E30: =MIN(Detailed!AA45,Detailed!AB45,Detailed!AC45,Detailed!AD45,Detailed!AE45,Detailed!AF45,Detailed!AG45,Detailed!AH45,Detailed!AI45,Detailed!AJ45,Detailed!AK45,Detailed!AL45)
B31: Ending cash (year end) | C31: =Detailed!N45 | D31: =Detailed!Z45 | E31: =Detailed!AL45

Sheet Detailed
B1: PUT YOUR STARTUP NAME HERE — 3-Year Projection Details
B2: Last Updated: | C2: 46196
B3: Active Case: | C3: =IF('Case Filter'!$C$1=0,"Base Case",IF('Case Filter'!$C$1=1,"Upside Case",IF('Case Filter'!$C$1=2,"Downside Case","Upside-Upside Case")))
B5: ($ Actual) | C5: M1 | D5: M2 | E5: M3 | F5: M4 | G5: M5 | H5: M6 | I5: M7 | J5: M8 | K5: M9 | L5: M10 | M5: M11 | N5: M12 | O5: M13 | P5: M14 | Q5: M15 | R5: M16 | S5: M17 | T5: M18 | U5: M19 | V5: M20 | W5: M21 | X5: M22 | Y5: M23 | Z5: M24 | AA5: M25 | AB5: M26 | AC5: M27 | AD5: M28 | AE5: M29 | AF5: M30 | AG5: M31 | AH5: M32 | AI5: M33 | AJ5: M34 | AK5: M35 | AL5: M36
B7: User & Subscriber Build-Up
B8: Beginning free users | C8: 0 | D8: =C15 | E8: =D15 | F8: =E15 | G8: =F15 | H8: =G15 | I8: =H15 | J8: =I15 | K8: =J15 | ... AL8: =AK15
B9: New signups | C9: =INDEX('Case Filter'!C$8:C$11,'Case Filter'!$C$1+1) | D9: =INDEX('Case Filter'!D$8:D$11,'Case Filter'!$C$1+1) | E9: =INDEX('Case Filter'!E$8:E$11,'Case Filter'!$C$1+1) | F9: =INDEX('Case Filter'!F$8:F$11,'Case Filter'!$C$1+1) | G9: =INDEX('Case Filter'!G$8:G$11,'Case Filter'!$C$1+1) | H9: =INDEX('Case Filter'!H$8:H$11,'Case Filter'!$C$1+1) | I9: =INDEX('Case Filter'!I$8:I$11,'Case Filter'!$C$1+1) | J9: =INDEX('Case Filter'!J$8:J$11,'Case Filter'!$C$1+1) | ... AL9: =INDEX('Case Filter'!AL$8:AL$11,'Case Filter'!$C$1+1)
B10: New Pro subscribers | C10: =C9*INDEX('Case Filter'!C$15:C$18,'Case Filter'!$C$1+1) | D10: =D9*INDEX('Case Filter'!D$15:D$18,'Case Filter'!$C$1+1) | E10: =E9*INDEX('Case Filter'!E$15:E$18,'Case Filter'!$C$1+1) | F10: =F9*INDEX('Case Filter'!F$15:F$18,'Case Filter'!$C$1+1) | G10: =G9*INDEX('Case Filter'!G$15:G$18,'Case Filter'!$C$1+1) | H10: =H9*INDEX('Case Filter'!H$15:H$18,'Case Filter'!$C$1+1) | I10: =I9*INDEX('Case Filter'!I$15:I$18,'Case Filter'!$C$1+1) | J10: =J9*INDEX('Case Filter'!J$15:J$18,'Case Filter'!$C$1+1) | ... AL10: =AL9*INDEX('Case Filter'!AL$15:AL$18,'Case Filter'!$C$1+1)
B11: Pro churn | C11: 0 | D11: =C13*INDEX('Case Filter'!D$22:D$25,'Case Filter'!$C$1+1) | E11: =D13*INDEX('Case Filter'!E$22:E$25,'Case Filter'!$C$1+1) | F11: =E13*INDEX('Case Filter'!F$22:F$25,'Case Filter'!$C$1+1) | G11: =F13*INDEX('Case Filter'!G$22:G$25,'Case Filter'!$C$1+1) | H11: =G13*INDEX('Case Filter'!H$22:H$25,'Case Filter'!$C$1+1) | I11: =H13*INDEX('Case Filter'!I$22:I$25,'Case Filter'!$C$1+1) | J11: =I13*INDEX('Case Filter'!J$22:J$25,'Case Filter'!$C$1+1) | K11: =J13*INDEX('Case Filter'!K$22:K$25,'Case Filter'!$C$1+1) | ... AL11: =AK13*INDEX('Case Filter'!AL$22:AL$25,'Case Filter'!$C$1+1)
B12: Net new Pro subscribers | C12: =C10-C11 | D12: =D10-D11 | E12: =E10-E11 | F12: =F10-F11 | G12: =G10-G11 | H12: =H10-H11 | I12: =I10-I11 | J12: =J10-J11 | ... AL12: =AL10-AL11
B13: Ending Pro subscribers | C13: =C12 | D13: =C13+D12 | E13: =D13+E12 | F13: =E13+F12 | G13: =F13+G12 | H13: =G13+H12 | I13: =H13+I12 | J13: =I13+J12 | K13: =J13+K12 | ... AL13: =AK13+AL12
B14: Ending total registered users | C14: =C9 | D14: =C14+D9 | E14: =D14+E9 | F14: =E14+F9 | G14: =F14+G9 | H14: =G14+H9 | I14: =H14+I9 | J14: =I14+J9 | K14: =J14+K9 | ... AL14: =AK14+AL9
B15: Ending free users | C15: =C14-C13 | D15: =D14-D13 | E15: =E14-E13 | F15: =F14-F13 | G15: =G14-G13 | H15: =H14-H13 | I15: =I14-I13 | J15: =J14-J13 | ... AL15: =AL14-AL13
B16: Pro as % of total users | C16: =IF(C14=0,0,C13/C14) | D16: =IF(D14=0,0,D13/D14) | E16: =IF(E14=0,0,E13/E14) | F16: =IF(F14=0,0,F13/F14) | G16: =IF(G14=0,0,G13/G14) | H16: =IF(H14=0,0,H13/H14) | I16: =IF(I14=0,0,I13/I14) | J16: =IF(J14=0,0,J13/J14) | ... AL16: =IF(AL14=0,0,AL13/AL14)
B18: Revenue & Gross Margin
B19: Gross MRR | C19: =C13*'Case Filter'!$C$42 | D19: =D13*'Case Filter'!$C$42 | E19: =E13*'Case Filter'!$C$42 | F19: =F13*'Case Filter'!$C$42 | G19: =G13*'Case Filter'!$C$42 | H19: =H13*'Case Filter'!$C$42 | I19: =I13*'Case Filter'!$C$42 | J19: =J13*'Case Filter'!$C$42 | ... AL19: =AL13*'Case Filter'!$C$42
B20: Stripe fees | C20: =C13*'Case Filter'!$C$43 | D20: =D13*'Case Filter'!$C$43 | E20: =E13*'Case Filter'!$C$43 | F20: =F13*'Case Filter'!$C$43 | G20: =G13*'Case Filter'!$C$43 | H20: =H13*'Case Filter'!$C$43 | I20: =I13*'Case Filter'!$C$43 | J20: =J13*'Case Filter'!$C$43 | ... AL20: =AL13*'Case Filter'!$C$43
B21: Net revenue | C21: =C19-C20 | D21: =D19-D20 | E21: =E19-E20 | F21: =F19-F20 | G21: =G19-G20 | H21: =H19-H20 | I21: =I19-I20 | J21: =J19-J20 | ... AL21: =AL19-AL20
B22: Variable COGS — AI Composer | C22: =C13*INDEX('Case Filter'!C$29:C$32,'Case Filter'!$C$1+1)*'Case Filter'!$C$44 | D22: =D13*INDEX('Case Filter'!D$29:D$32,'Case Filter'!$C$1+1)*'Case Filter'!$C$44 | E22: =E13*INDEX('Case Filter'!E$29:E$32,'Case Filter'!$C$1+1)*'Case Filter'!$C$44 | F22: =F13*INDEX('Case Filter'!F$29:F$32,'Case Filter'!$C$1+1)*'Case Filter'!$C$44 | G22: =G13*INDEX('Case Filter'!G$29:G$32,'Case Filter'!$C$1+1)*'Case Filter'!$C$44 | H22: =H13*INDEX('Case Filter'!H$29:H$32,'Case Filter'!$C$1+1)*'Case Filter'!$C$44 | I22: =I13*INDEX('Case Filter'!I$29:I$32,'Case Filter'!$C$1+1)*'Case Filter'!$C$44 | J22: =J13*INDEX('Case Filter'!J$29:J$32,'Case Filter'!$C$1+1)*'Case Filter'!$C$44 | ... AL22: =AL13*INDEX('Case Filter'!AL$29:AL$32,'Case Filter'!$C$1+1)*'Case Filter'!$C$44
B23: Variable COGS — other per Pro | C23: =C13*'Case Filter'!$C$45 | D23: =D13*'Case Filter'!$C$45 | E23: =E13*'Case Filter'!$C$45 | F23: =F13*'Case Filter'!$C$45 | G23: =G13*'Case Filter'!$C$45 | H23: =H13*'Case Filter'!$C$45 | I23: =I13*'Case Filter'!$C$45 | J23: =J13*'Case Filter'!$C$45 | ... AL23: =AL13*'Case Filter'!$C$45
B24: Variable COGS — free user acquisition | C24: =(C9-C10)*'Case Filter'!$C$46 | D24: =(D9-D10)*'Case Filter'!$C$46 | E24: =(E9-E10)*'Case Filter'!$C$46 | F24: =(F9-F10)*'Case Filter'!$C$46 | G24: =(G9-G10)*'Case Filter'!$C$46 | H24: =(H9-H10)*'Case Filter'!$C$46 | I24: =(I9-I10)*'Case Filter'!$C$46 | J24: =(J9-J10)*'Case Filter'!$C$46 | ... AL24: =(AL9-AL10)*'Case Filter'!$C$46
B25: Total variable COGS | C25: =SUM(C22:C24) | D25: =SUM(D22:D24) | E25: =SUM(E22:E24) | F25: =SUM(F22:F24) | G25: =SUM(G22:G24) | H25: =SUM(H22:H24) | I25: =SUM(I22:I24) | J25: =SUM(J22:J24) | ... AL25: =SUM(AL22:AL24)
B26: Gross profit | C26: =C21-C25 | D26: =D21-D25 | E26: =E21-E25 | F26: =F21-F25 | G26: =G21-G25 | H26: =H21-H25 | I26: =I21-I25 | J26: =J21-J25 | ... AL26: =AL21-AL25
B27: Gross margin % | C27: =IF(C21=0,"NM",C26/C21) | D27: =IF(D21=0,"NM",D26/D21) | E27: =IF(E21=0,"NM",E26/E21) | F27: =IF(F21=0,"NM",F26/F21) | G27: =IF(G21=0,"NM",G26/G21) | H27: =IF(H21=0,"NM",H26/H21) | I27: =IF(I21=0,"NM",I26/I21) | J27: =IF(J21=0,"NM",J26/J21) | ... AL27: =IF(AL21=0,"NM",AL26/AL21)
B29: Operating Expenses
B30: Fixed infrastructure | C30: ='Case Filter'!$C$47 | D30: ='Case Filter'!$C$47 | E30: ='Case Filter'!$C$47 | F30: ='Case Filter'!$C$47 | G30: ='Case Filter'!$C$47 | H30: ='Case Filter'!$C$47 | I30: ='Case Filter'!$C$47 | J30: ='Case Filter'!$C$47 | ... AL30: ='Case Filter'!$C$47
B31: Founder / team salary | C31: ='Case Filter'!$C$48 | D31: ='Case Filter'!$C$48 | E31: ='Case Filter'!$C$48 | F31: ='Case Filter'!$C$48 | G31: ='Case Filter'!$C$48 | H31: ='Case Filter'!$C$48 | I31: ='Case Filter'!$C$48 | J31: ='Case Filter'!$C$48 | ... N31: ='Case Filter'!$C$48 | O31: ='Case Filter'!$C$49 | P31: ='Case Filter'!$C$49 | Q31: ='Case Filter'!$C$49 | R31: ='Case Filter'!$C$49 | S31: ='Case Filter'!$C$49 | T31: ='Case Filter'!$C$49 | U31: ='Case Filter'!$C$49 | V31: ='Case Filter'!$C$49 | ... Z31: ='Case Filter'!$C$49 | AA31: ='Case Filter'!$C$50 | AB31: ='Case Filter'!$C$50 | AC31: ='Case Filter'!$C$50 | AD31: ='Case Filter'!$C$50 | AE31: ='Case Filter'!$C$50 | AF31: ='Case Filter'!$C$50 | AG31: ='Case Filter'!$C$50 | AH31: ='Case Filter'!$C$50 | ... AL31: ='Case Filter'!$C$50
B32: Contract development | C32: ='Case Filter'!$C$51 | D32: ='Case Filter'!$C$51 | E32: ='Case Filter'!$C$51 | F32: ='Case Filter'!$C$51 | G32: ='Case Filter'!$C$51 | H32: ='Case Filter'!$C$51 | I32: ='Case Filter'!$C$51 | J32: ='Case Filter'!$C$51 | ... AL32: ='Case Filter'!$C$51
B33: Legal & accounting | C33: ='Case Filter'!$C$52 | D33: ='Case Filter'!$C$52 | E33: ='Case Filter'!$C$52 | F33: ='Case Filter'!$C$52 | G33: ='Case Filter'!$C$52 | H33: ='Case Filter'!$C$52 | I33: ='Case Filter'!$C$52 | J33: ='Case Filter'!$C$52 | ... AL33: ='Case Filter'!$C$52
B34: Paid marketing | C34: =INDEX('Case Filter'!C$36:C$39,'Case Filter'!$C$1+1) | D34: =INDEX('Case Filter'!D$36:D$39,'Case Filter'!$C$1+1) | E34: =INDEX('Case Filter'!E$36:E$39,'Case Filter'!$C$1+1) | F34: =INDEX('Case Filter'!F$36:F$39,'Case Filter'!$C$1+1) | G34: =INDEX('Case Filter'!G$36:G$39,'Case Filter'!$C$1+1) | H34: =INDEX('Case Filter'!H$36:H$39,'Case Filter'!$C$1+1) | I34: =INDEX('Case Filter'!I$36:I$39,'Case Filter'!$C$1+1) | J34: =INDEX('Case Filter'!J$36:J$39,'Case Filter'!$C$1+1) | ... AL34: =INDEX('Case Filter'!AL$36:AL$39,'Case Filter'!$C$1+1)
B35: One-time costs | C35: =IF(1=1,'Case Filter'!$C$54,0) | D35: =IF(2=1,'Case Filter'!$C$54,0) | E35: =IF(3=1,'Case Filter'!$C$54,0) | F35: =IF(4=1,'Case Filter'!$C$54,0) | G35: =IF(5=1,'Case Filter'!$C$54,0) | H35: =IF(6=1,'Case Filter'!$C$54,0) | I35: =IF(7=1,'Case Filter'!$C$54,0) | J35: =IF(8=1,'Case Filter'!$C$54,0) | K35: =IF(9=1,'Case Filter'!$C$54,0) | L35: =IF(10=1,'Case Filter'!$C$54,0) | M35: =IF(11=1,'Case Filter'!$C$54,0) | N35: =IF(12=1,'Case Filter'!$C$54,0) | O35: =IF(13=1,'Case Filter'!$C$54,0) | P35: =IF(14=1,'Case Filter'!$C$54,0) | Q35: =IF(15=1,'Case Filter'!$C$54,0) | R35: =IF(16=1,'Case Filter'!$C$54,0) | S35: =IF(17=1,'Case Filter'!$C$54,0) | T35: =IF(18=1,'Case Filter'!$C$54,0) | U35: =IF(19=1,'Case Filter'!$C$54,0) | V35: =IF(20=1,'Case Filter'!$C$54,0) | W35: =IF(21=1,'Case Filter'!$C$54,0) | X35: =IF(22=1,'Case Filter'!$C$54,0) | Y35: =IF(23=1,'Case Filter'!$C$54,0) | Z35: =IF(24=1,'Case Filter'!$C$54,0) | AA35: =IF(25=1,'Case Filter'!$C$54,0) | AB35: =IF(26=1,'Case Filter'!$C$54,0) | AC35: =IF(27=1,'Case Filter'!$C$54,0) | AD35: =IF(28=1,'Case Filter'!$C$54,0) | AE35: =IF(29=1,'Case Filter'!$C$54,0) | AF35: =IF(30=1,'Case Filter'!$C$54,0) | AG35: =IF(31=1,'Case Filter'!$C$54,0) | AH35: =IF(32=1,'Case Filter'!$C$54,0) | AI35: =IF(33=1,'Case Filter'!$C$54,0) | AJ35: =IF(34=1,'Case Filter'!$C$54,0) | AK35: =IF(35=1,'Case Filter'!$C$54,0) | AL35: =IF(36=1,'Case Filter'!$C$54,0)
B36: Total operating expenses | C36: =SUM(C30:C35) | D36: =SUM(D30:D35) | E36: =SUM(E30:E35) | F36: =SUM(F30:F35) | G36: =SUM(G30:G35) | H36: =SUM(H30:H35) | I36: =SUM(I30:I35) | J36: =SUM(J30:J35) | ... AL36: =SUM(AL30:AL35)
B38: EBITDA | C38: =C26-C36 | D38: =D26-D36 | E38: =E26-E36 | F38: =F26-F36 | G38: =G26-G36 | H38: =H26-H36 | I38: =I26-I36 | J38: =J26-J36 | ... AL38: =AL26-AL36
B39: Capital expenditures | C39: 0 | D39: 0 | E39: 0 | F39: 0 | G39: 0 | H39: 0 | I39: 0 | J39: 0 | K39: 0 | L39: 0 | M39: 0 | N39: 0 | O39: 0 | P39: 0 | Q39: 0 | R39: 0 | S39: 0 | T39: 0 | U39: 0 | V39: 0 | W39: 0 | X39: 0 | Y39: 0 | Z39: 0 | AA39: 0 | AB39: 0 | AC39: 0 | AD39: 0 | AE39: 0 | AF39: 0 | AG39: 0 | AH39: 0 | AI39: 0 | AJ39: 0 | AK39: 0 | AL39: 0
B40: Free cash flow | C40: =C38-C39 | D40: =D38-D39 | E40: =E38-E39 | F40: =F38-F39 | G40: =G38-G39 | H40: =H38-H39 | I40: =I38-I39 | J40: =J38-J39 | ... AL40: =AL38-AL39
B42: Cash & Funding
B43: Funding in | C43: =IF(1=1,'Case Filter'!$C$53,0) | D43: =IF(2=1,'Case Filter'!$C$53,0) | E43: =IF(3=1,'Case Filter'!$C$53,0) | F43: =IF(4=1,'Case Filter'!$C$53,0) | G43: =IF(5=1,'Case Filter'!$C$53,0) | H43: =IF(6=1,'Case Filter'!$C$53,0) | I43: =IF(7=1,'Case Filter'!$C$53,0) | J43: =IF(8=1,'Case Filter'!$C$53,0) | K43: =IF(9=1,'Case Filter'!$C$53,0) | L43: =IF(10=1,'Case Filter'!$C$53,0) | M43: =IF(11=1,'Case Filter'!$C$53,0) | N43: =IF(12=1,'Case Filter'!$C$53,0) | O43: =IF(13=1,'Case Filter'!$C$53,0) | P43: =IF(14=1,'Case Filter'!$C$53,0) | Q43: =IF(15=1,'Case Filter'!$C$53,0) | R43: =IF(16=1,'Case Filter'!$C$53,0) | S43: =IF(17=1,'Case Filter'!$C$53,0) | T43: =IF(18=1,'Case Filter'!$C$53,0) | U43: =IF(19=1,'Case Filter'!$C$53,0) | V43: =IF(20=1,'Case Filter'!$C$53,0) | W43: =IF(21=1,'Case Filter'!$C$53,0) | X43: =IF(22=1,'Case Filter'!$C$53,0) | Y43: =IF(23=1,'Case Filter'!$C$53,0) | Z43: =IF(24=1,'Case Filter'!$C$53,0) | AA43: =IF(25=1,'Case Filter'!$C$53,0) | AB43: =IF(26=1,'Case Filter'!$C$53,0) | AC43: =IF(27=1,'Case Filter'!$C$53,0) | AD43: =IF(28=1,'Case Filter'!$C$53,0) | AE43: =IF(29=1,'Case Filter'!$C$53,0) | AF43: =IF(30=1,'Case Filter'!$C$53,0) | AG43: =IF(31=1,'Case Filter'!$C$53,0) | AH43: =IF(32=1,'Case Filter'!$C$53,0) | AI43: =IF(33=1,'Case Filter'!$C$53,0) | AJ43: =IF(34=1,'Case Filter'!$C$53,0) | AK43: =IF(35=1,'Case Filter'!$C$53,0) | AL43: =IF(36=1,'Case Filter'!$C$53,0)
B44: Beginning cash | C44: 0 | D44: =C45 | E44: =D45 | F44: =E45 | G44: =F45 | H44: =G45 | I44: =H45 | J44: =I45 | K44: =J45 | ... AL44: =AK45
B45: Ending cash | C45: =C44+C43+C40 | D45: =D44+D43+D40 | E45: =E44+E43+E40 | F45: =F44+F43+F40 | G45: =G44+G43+G40 | H45: =H44+H43+H40 | I45: =I44+I43+I40 | J45: =J44+J43+J40 | ... AL45: =AL44+AL43+AL40
B46: Runway (months if burning) | C46: =IF(C40>=0,"Profitable",IF(C45<=0,0,C45/ABS(C40))) | D46: =IF(D40>=0,"Profitable",IF(D45<=0,0,D45/ABS(D40))) | E46: =IF(E40>=0,"Profitable",IF(E45<=0,0,E45/ABS(E40))) | F46: =IF(F40>=0,"Profitable",IF(F45<=0,0,F45/ABS(F40))) | G46: =IF(G40>=0,"Profitable",IF(G45<=0,0,G45/ABS(G40))) | H46: =IF(H40>=0,"Profitable",IF(H45<=0,0,H45/ABS(H40))) | I46: =IF(I40>=0,"Profitable",IF(I45<=0,0,I45/ABS(I40))) | J46: =IF(J40>=0,"Profitable",IF(J45<=0,0,J45/ABS(J40))) | ... AL46: =IF(AL40>=0,"Profitable",IF(AL45<=0,0,AL45/ABS(AL40)))

Sheet Assumptions
B2: Model Assumptions & Notes
B5: UNIT ECONOMICS — CALIBRATE FOR YOUR PRODUCT
B7: Replace Composer / free-tier COGS with your marginal cost per active user.
B8: At P50 ($0.104/run): Composer COGS alone ≈ $31.20 → total COGS ≈ $33.
B9: Net revenue after Stripe ≈ $14.26 → loss ≈ $19/user/month.
B11: Break-even at P50: ~130 runs/mo (~4 runs/day). At P25 (small): ~11 runs/day.
B12: Code cap today: 20 runs/user/UTC day — 10/day is allowed.
B14: If even 5% of Pro subs behave this way, blend COGS into Case Filter
B15: Composer runs / Pro sub / month (e.g. bump from 25 → 40+ for conservative base).
B16: • Non-composer variable/Pro/mo: $0.70 (Voyage, Postmark, Supabase alloc.)
B17: • Free user lifetime COGS: $2.80 (5 compositions, ~20 composer runs)
B18: • Stripe: $0.735/charge (2.9% + $0.30 on $15)
... B63: Compare to: early Notion, Slack freemium breakout — top ~0.1% of startups.

Sheet Case Filter
B1: CASE TOGGLE | C1: 0
B2: C1: 0=Base | 1=Upside | 2=Downside | 3=Upside-Upside (1M users by Y2)
B4: ($ Actual) | C4: M1 | D4: M2 | E4: M3 | F4: M4 | G4: M5 | H4: M6 | I4: M7 | J4: M8 | K4: M9 | L4: M10 | M4: M11 | N4: M12 | O4: M13 | P4: M14 | Q4: M15 | R4: M16 | S4: M17 | T4: M18 | U4: M19 | V4: M20 | W4: M21 | X4: M22 | Y4: M23 | Z4: M24 | AA4: M25 | AB4: M26 | AC4: M27 | AD4: M28 | AE4: M29 | AF4: M30 | AG4: M31 | AH4: M32 | AI4: M33 | AJ4: M34 | AK4: M35 | AL4: M36
B6: New user signups / month ← USE GROWTH CURVE EDITOR FOR BASE CASE
B7: ACTIVE CASE | C7: =INDEX(C$8:C$11,$C$1+1) | D7: =INDEX(D$8:D$11,$C$1+1) | E7: =INDEX(E$8:E$11,$C$1+1) | F7: =INDEX(F$8:F$11,$C$1+1) | G7: =INDEX(G$8:G$11,$C$1+1) | H7: =INDEX(H$8:H$11,$C$1+1) | I7: =INDEX(I$8:I$11,$C$1+1) | J7: =INDEX(J$8:J$11,$C$1+1) | ... AL7: =INDEX(AL$8:AL$11,$C$1+1)
A8: 1 | B8: Base Case | C8: 10 | D8: 10 | E8: 10 | F8: 10 | G8: 10 | H8: 10 | I8: 10 | J8: 10 | K8: 10 | L8: 10 | M8: 10 | N8: 10 | O8: 10 | P8: 10 | Q8: 10 | R8: 10 | S8: 10 | T8: 10 | U8: 10 | V8: 10 | W8: 10 | X8: 10 | Y8: 10 | Z8: 10 | AA8: 10 | AB8: 10 | AC8: 10 | AD8: 10 | AE8: 10 | AF8: 10 | AG8: 10 | AH8: 10 | AI8: 10 | AJ8: 10 | AK8: 10 | AL8: 10
A9: 2 | B9: Upside Case | C9: 10 | D9: 10 | E9: 10 | F9: 10 | G9: 10 | H9: 10 | I9: 10 | J9: 10 | K9: 10 | L9: 10 | M9: 10 | N9: 10 | O9: 10 | P9: 10 | Q9: 10 | R9: 10 | S9: 10 | T9: 10 | U9: 10 | V9: 10 | W9: 10 | X9: 10 | Y9: 10 | Z9: 10 | AA9: 10 | AB9: 10 | AC9: 10 | AD9: 10 | AE9: 10 | AF9: 10 | AG9: 10 | AH9: 10 | AI9: 10 | AJ9: 10 | AK9: 10 | AL9: 10
A10: 3 | B10: Downside Case | C10: 10 | D10: 10 | E10: 10 | F10: 10 | G10: 10 | H10: 10 | I10: 10 | J10: 10 | K10: 10 | L10: 10 | M10: 10 | N10: 10 | O10: 10 | P10: 10 | Q10: 10 | R10: 10 | S10: 10 | T10: 10 | U10: 10 | V10: 10 | W10: 10 | X10: 10 | Y10: 10 | Z10: 10 | AA10: 10 | AB10: 10 | AC10: 10 | AD10: 10 | AE10: 10 | AF10: 10 | AG10: 10 | AH10: 10 | AI10: 10 | AJ10: 10 | AK10: 10 | AL10: 10
A11: 4 | B11: Upside-Upside Case | C11: 10 | D11: 10 | E11: 10 | F11: 10 | G11: 10 | H11: 10 | I11: 10 | J11: 10 | K11: 10 | L11: 10 | M11: 10 | N11: 10 | O11: 10 | P11: 10 | Q11: 10 | R11: 10 | S11: 10 | T11: 10 | U11: 10 | V11: 10 | W11: 10 | X11: 10 | Y11: 10 | Z11: 10 | AA11: 10 | AB11: 10 | AC11: 10 | AD11: 10 | AE11: 10 | AF11: 10 | AG11: 10 | AH11: 10 | AI11: 10 | AJ11: 10 | AK11: 10 | AL11: 10
B13: Free → Pro conversion rate (new signups, same month)
B14: ACTIVE CASE | C14: =INDEX(C$15:C$18,$C$1+1) | D14: =INDEX(D$15:D$18,$C$1+1) | E14: =INDEX(E$15:E$18,$C$1+1) | F14: =INDEX(F$15:F$18,$C$1+1) | G14: =INDEX(G$15:G$18,$C$1+1) | H14: =INDEX(H$15:H$18,$C$1+1) | I14: =INDEX(I$15:I$18,$C$1+1) | J14: =INDEX(J$15:J$18,$C$1+1) | ... AL14: =INDEX(AL$15:AL$18,$C$1+1)
A15: 1 | B15: Base Case | C15: 0.05 | D15: 0.05 | E15: 0.05 | F15: 0.05 | G15: 0.05 | H15: 0.05 | I15: 0.05 | J15: 0.05 | K15: 0.05 | L15: 0.05 | M15: 0.05 | N15: 0.05 | O15: 0.05 | P15: 0.05 | Q15: 0.05 | R15: 0.05 | S15: 0.05 | T15: 0.05 | U15: 0.05 | V15: 0.05 | W15: 0.05 | X15: 0.05 | Y15: 0.05 | Z15: 0.05 | AA15: 0.05 | AB15: 0.05 | AC15: 0.05 | AD15: 0.05 | AE15: 0.05 | AF15: 0.05 | AG15: 0.05 | AH15: 0.05 | AI15: 0.05 | AJ15: 0.05 | AK15: 0.05 | AL15: 0.05
A16: 2 | B16: Upside Case | C16: 0.05 | D16: 0.05 | E16: 0.05 | F16: 0.05 | G16: 0.05 | H16: 0.05 | I16: 0.05 | J16: 0.05 | K16: 0.05 | L16: 0.05 | M16: 0.05 | N16: 0.05 | O16: 0.05 | P16: 0.05 | Q16: 0.05 | R16: 0.05 | S16: 0.05 | T16: 0.05 | U16: 0.05 | V16: 0.05 | W16: 0.05 | X16: 0.05 | Y16: 0.05 | Z16: 0.05 | AA16: 0.05 | AB16: 0.05 | AC16: 0.05 | AD16: 0.05 | AE16: 0.05 | AF16: 0.05 | AG16: 0.05 | AH16: 0.05 | AI16: 0.05 | AJ16: 0.05 | AK16: 0.05 | AL16: 0.05
A17: 3 | B17: Downside Case | C17: 0.05 | D17: 0.05 | E17: 0.05 | F17: 0.05 | G17: 0.05 | H17: 0.05 | I17: 0.05 | J17: 0.05 | K17: 0.05 | L17: 0.05 | M17: 0.05 | N17: 0.05 | O17: 0.05 | P17: 0.05 | Q17: 0.05 | R17: 0.05 | S17: 0.05 | T17: 0.05 | U17: 0.05 | V17: 0.05 | W17: 0.05 | X17: 0.05 | Y17: 0.05 | Z17: 0.05 | AA17: 0.05 | AB17: 0.05 | AC17: 0.05 | AD17: 0.05 | AE17: 0.05 | AF17: 0.05 | AG17: 0.05 | AH17: 0.05 | AI17: 0.05 | AJ17: 0.05 | AK17: 0.05 | AL17: 0.05
A18: 4 | B18: Upside-Upside Case | C18: 0.05 | D18: 0.05 | E18: 0.05 | F18: 0.05 | G18: 0.05 | H18: 0.05 | I18: 0.05 | J18: 0.05 | K18: 0.05 | L18: 0.05 | M18: 0.05 | N18: 0.05 | O18: 0.05 | P18: 0.05 | Q18: 0.05 | R18: 0.05 | S18: 0.05 | T18: 0.05 | U18: 0.05 | V18: 0.05 | W18: 0.05 | X18: 0.05 | Y18: 0.05 | Z18: 0.05 | AA18: 0.05 | AB18: 0.05 | AC18: 0.05 | AD18: 0.05 | AE18: 0.05 | AF18: 0.05 | AG18: 0.05 | AH18: 0.05 | AI18: 0.05 | AJ18: 0.05 | AK18: 0.05 | AL18: 0.05
B20: Pro monthly churn rate
B21: ACTIVE CASE | C21: =INDEX(C$22:C$25,$C$1+1) | D21: =INDEX(D$22:D$25,$C$1+1) | E21: =INDEX(E$22:E$25,$C$1+1) | F21: =INDEX(F$22:F$25,$C$1+1) | G21: =INDEX(G$22:G$25,$C$1+1) | H21: =INDEX(H$22:H$25,$C$1+1) | I21: =INDEX(I$22:I$25,$C$1+1) | J21: =INDEX(J$22:J$25,$C$1+1) | ... AL21: =INDEX(AL$22:AL$25,$C$1+1)
A22: 1 | B22: Base Case | C22: 0.06 | D22: 0.06 | E22: 0.06 | F22: 0.06 | G22: 0.06 | H22: 0.06 | I22: 0.06 | J22: 0.06 | K22: 0.06 | L22: 0.06 | M22: 0.06 | N22: 0.06 | O22: 0.06 | P22: 0.06 | Q22: 0.06 | R22: 0.06 | S22: 0.06 | T22: 0.06 | U22: 0.06 | V22: 0.06 | W22: 0.06 | X22: 0.06 | Y22: 0.06 | Z22: 0.06 | AA22: 0.06 | AB22: 0.06 | AC22: 0.06 | AD22: 0.06 | AE22: 0.06 | AF22: 0.06 | AG22: 0.06 | AH22: 0.06 | AI22: 0.06 | AJ22: 0.06 | AK22: 0.06 | AL22: 0.06
A23: 2 | B23: Upside Case | C23: 0.06 | D23: 0.06 | E23: 0.06 | F23: 0.06 | G23: 0.06 | H23: 0.06 | I23: 0.06 | J23: 0.06 | K23: 0.06 | L23: 0.06 | M23: 0.06 | N23: 0.06 | O23: 0.06 | P23: 0.06 | Q23: 0.06 | R23: 0.06 | S23: 0.06 | T23: 0.06 | U23: 0.06 | V23: 0.06 | W23: 0.06 | X23: 0.06 | Y23: 0.06 | Z23: 0.06 | AA23: 0.06 | AB23: 0.06 | AC23: 0.06 | AD23: 0.06 | AE23: 0.06 | AF23: 0.06 | AG23: 0.06 | AH23: 0.06 | AI23: 0.06 | AJ23: 0.06 | AK23: 0.06 | AL23: 0.06
A24: 3 | B24: Downside Case | C24: 0.06 | D24: 0.06 | E24: 0.06 | F24: 0.06 | G24: 0.06 | H24: 0.06 | I24: 0.06 | J24: 0.06 | K24: 0.06 | L24: 0.06 | M24: 0.06 | N24: 0.06 | O24: 0.06 | P24: 0.06 | Q24: 0.06 | R24: 0.06 | S24: 0.06 | T24: 0.06 | U24: 0.06 | V24: 0.06 | W24: 0.06 | X24: 0.06 | Y24: 0.06 | Z24: 0.06 | AA24: 0.06 | AB24: 0.06 | AC24: 0.06 | AD24: 0.06 | AE24: 0.06 | AF24: 0.06 | AG24: 0.06 | AH24: 0.06 | AI24: 0.06 | AJ24: 0.06 | AK24: 0.06 | AL24: 0.06
A25: 4 | B25: Upside-Upside Case | C25: 0.06 | D25: 0.06 | E25: 0.06 | F25: 0.06 | G25: 0.06 | H25: 0.06 | I25: 0.06 | J25: 0.06 | K25: 0.06 | L25: 0.06 | M25: 0.06 | N25: 0.06 | O25: 0.06 | P25: 0.06 | Q25: 0.06 | R25: 0.06 | S25: 0.06 | T25: 0.06 | U25: 0.06 | V25: 0.06 | W25: 0.06 | X25: 0.06 | Y25: 0.06 | Z25: 0.06 | AA25: 0.06 | AB25: 0.06 | AC25: 0.06 | AD25: 0.06 | AE25: 0.06 | AF25: 0.06 | AG25: 0.06 | AH25: 0.06 | AI25: 0.06 | AJ25: 0.06 | AK25: 0.06 | AL25: 0.06
B27: Composer runs / Pro sub / month
B28: ACTIVE CASE | C28: =INDEX(C$29:C$32,$C$1+1) | D28: =INDEX(D$29:D$32,$C$1+1) | E28: =INDEX(E$29:E$32,$C$1+1) | F28: =INDEX(F$29:F$32,$C$1+1) | G28: =INDEX(G$29:G$32,$C$1+1) | H28: =INDEX(H$29:H$32,$C$1+1) | I28: =INDEX(I$29:I$32,$C$1+1) | J28: =INDEX(J$29:J$32,$C$1+1) | ... AL28: =INDEX(AL$29:AL$32,$C$1+1)
A29: 1 | B29: Base Case | C29: 25 | D29: 25 | E29: 25 | F29: 25 | G29: 25 | H29: 25 | I29: 25 | J29: 25 | K29: 25 | L29: 25 | M29: 25 | N29: 25 | O29: 25 | P29: 25 | Q29: 25 | R29: 25 | S29: 25 | T29: 25 | U29: 25 | V29: 25 | W29: 25 | X29: 25 | Y29: 25 | Z29: 25 | AA29: 25 | AB29: 25 | AC29: 25 | AD29: 25 | AE29: 25 | AF29: 25 | AG29: 25 | AH29: 25 | AI29: 25 | AJ29: 25 | AK29: 25 | AL29: 25
A30: 2 | B30: Upside Case | C30: 25 | D30: 25 | E30: 25 | F30: 25 | G30: 25 | H30: 25 | I30: 25 | J30: 25 | K30: 25 | L30: 25 | M30: 25 | N30: 25 | O30: 25 | P30: 25 | Q30: 25 | R30: 25 | S30: 25 | T30: 25 | U30: 25 | V30: 25 | W30: 25 | X30: 25 | Y30: 25 | Z30: 25 | AA30: 25 | AB30: 25 | AC30: 25 | AD30: 25 | AE30: 25 | AF30: 25 | AG30: 25 | AH30: 25 | AI30: 25 | AJ30: 25 | AK30: 25 | AL30: 25
A31: 3 | B31: Downside Case | C31: 25 | D31: 25 | E31: 25 | F31: 25 | G31: 25 | H31: 25 | I31: 25 | J31: 25 | K31: 25 | L31: 25 | M31: 25 | N31: 25 | O31: 25 | P31: 25 | Q31: 25 | R31: 25 | S31: 25 | T31: 25 | U31: 25 | V31: 25 | W31: 25 | X31: 25 | Y31: 25 | Z31: 25 | AA31: 25 | AB31: 25 | AC31: 25 | AD31: 25 | AE31: 25 | AF31: 25 | AG31: 25 | AH31: 25 | AI31: 25 | AJ31: 25 | AK31: 25 | AL31: 25
A32: 4 | B32: Upside-Upside Case | C32: 25 | D32: 25 | E32: 25 | F32: 25 | G32: 25 | H32: 25 | I32: 25 | J32: 25 | K32: 25 | L32: 25 | M32: 25 | N32: 25 | O32: 25 | P32: 25 | Q32: 25 | R32: 25 | S32: 25 | T32: 25 | U32: 25 | V32: 25 | W32: 25 | X32: 25 | Y32: 25 | Z32: 25 | AA32: 25 | AB32: 25 | AC32: 25 | AD32: 25 | AE32: 25 | AF32: 25 | AG32: 25 | AH32: 25 | AI32: 25 | AJ32: 25 | AK32: 25 | AL32: 25
B34: Paid marketing spend / month ($)
B35: ACTIVE CASE | C35: =INDEX(C$36:C$39,$C$1+1) | D35: =INDEX(D$36:D$39,$C$1+1) | E35: =INDEX(E$36:E$39,$C$1+1) | F35: =INDEX(F$36:F$39,$C$1+1) | G35: =INDEX(G$36:G$39,$C$1+1) | H35: =INDEX(H$36:H$39,$C$1+1) | I35: =INDEX(I$36:I$39,$C$1+1) | J35: =INDEX(J$36:J$39,$C$1+1) | ... AL35: =INDEX(AL$36:AL$39,$C$1+1)
A36: 1 | B36: Base Case | C36: 300 | D36: 300 | E36: 300 | F36: 300 | G36: 300 | H36: 300 | I36: 300 | J36: 300 | K36: 300 | L36: 300 | M36: 300 | N36: 300 | O36: 300 | P36: 300 | Q36: 300 | R36: 300 | S36: 300 | T36: 300 | U36: 300 | V36: 300 | W36: 300 | X36: 300 | Y36: 300 | Z36: 300 | AA36: 300 | AB36: 300 | AC36: 300 | AD36: 300 | AE36: 300 | AF36: 300 | AG36: 300 | AH36: 300 | AI36: 300 | AJ36: 300 | AK36: 300 | AL36: 300
A37: 2 | B37: Upside Case | C37: 300 | D37: 300 | E37: 300 | F37: 300 | G37: 300 | H37: 300 | I37: 300 | J37: 300 | K37: 300 | L37: 300 | M37: 300 | N37: 300 | O37: 300 | P37: 300 | Q37: 300 | R37: 300 | S37: 300 | T37: 300 | U37: 300 | V37: 300 | W37: 300 | X37: 300 | Y37: 300 | Z37: 300 | AA37: 300 | AB37: 300 | AC37: 300 | AD37: 300 | AE37: 300 | AF37: 300 | AG37: 300 | AH37: 300 | AI37: 300 | AJ37: 300 | AK37: 300 | AL37: 300
A38: 3 | B38: Downside Case | C38: 300 | D38: 300 | E38: 300 | F38: 300 | G38: 300 | H38: 300 | I38: 300 | J38: 300 | K38: 300 | L38: 300 | M38: 300 | N38: 300 | O38: 300 | P38: 300 | Q38: 300 | R38: 300 | S38: 300 | T38: 300 | U38: 300 | V38: 300 | W38: 300 | X38: 300 | Y38: 300 | Z38: 300 | AA38: 300 | AB38: 300 | AC38: 300 | AD38: 300 | AE38: 300 | AF38: 300 | AG38: 300 | AH38: 300 | AI38: 300 | AJ38: 300 | AK38: 300 | AL38: 300
A39: 4 | B39: Upside-Upside Case | C39: 300 | D39: 300 | E39: 300 | F39: 300 | G39: 300 | H39: 300 | I39: 300 | J39: 300 | K39: 300 | L39: 300 | M39: 300 | N39: 300 | O39: 300 | P39: 300 | Q39: 300 | R39: 300 | S39: 300 | T39: 300 | U39: 300 | V39: 300 | W39: 300 | X39: 300 | Y39: 300 | Z39: 300 | AA39: 300 | AB39: 300 | AC39: 300 | AD39: 300 | AE39: 300 | AF39: 300 | AG39: 300 | AH39: 300 | AI39: 300 | AJ39: 300 | AK39: 300 | AL39: 300
B41: Unit Economics & Fixed Costs
B42: Pro subscription price / month ($) ← SET YOUR PRICE | C42: 0
B43: Stripe fee per charge ($) | C43: 0.735
B44: Composer COGS per run ($) | C44: 0.1
B45: Non-composer variable COGS / Pro / month ($) | C45: 0.7
B46: Free user lifetime COGS ($) | C46: 2.8
B47: Fixed infrastructure / month ($) | C47: 57
...
